// async错误捕获.js


// 捕捉错误
// 既然.then(..)不用写了，那么.catch(..)也不用写，可以直接用标准的try catch语法捕捉错误。

// 当然 async 函数返回一个promise对象，当然可以使用then方法

var sleep = function (time) {
    return new Promise(function (resolve, reject) {
        setTimeout(function () {
            // 模拟出错了，返回 ‘error’
            reject('error');
        }, time);
    })
};

var start = async function () {
    try {
        console.log('start');
        await sleep(3000); // 这里得到了一个返回错误        
        // 所以以下代码不会被执行了
        console.log('end');
    } catch (err) {
        console.log(err); // 这里捕捉到错误 `error`
    }
};

start();